from mcje.minecraft import Minecraft
import param_MCJE as param
import random as rd

mc = Minecraft.create(port=param.PORT_MC)


# ------------- spawn ------------- #
def leg(x, y, z, WOOL):
    mc.setBlocks(x, y, z, x + 7, y + 1, z + 7, param.BROWN_TERRACOTTA)
    mc.setBlocks(x + 2, y, z + 2, x + 7, y + 1, z + 5, param.WHITE_TERRACOTTA)
    mc.setBlocks(x, y + 2, z, x, y + 11, z + 7, param.WHITE_TERRACOTTA)
    mc.setBlocks(x, y + 2, z, x + 7, y + 11, z, param.WHITE_TERRACOTTA)
    mc.setBlocks(x + 7, y + 2, z, x + 7, y + 11, z + 7, param.WHITE_TERRACOTTA)
    mc.setBlocks(x, y + 2, z + 7, x + 7, y + 11, z + 7, param.WHITE_TERRACOTTA)
    mc.setBlocks(x - 1, y + 12, z - 1, x - 1, y + 21, z + 8, WOOL)
    mc.setBlocks(x + 8, y + 12, z - 1, x + 8, y + 21, z + 8, WOOL)
    mc.setBlocks(x - 1, y + 12, z - 1, x + 8, y + 21, z - 1, WOOL)
    mc.setBlocks(x - 1, y + 12, z + 8, x + 8, y + 21, z + 8, WOOL)


def body(x, y, z, WOOL):
    mc.setBlocks(x - 6, y + 22, z - 2, x + 33, y + 22, z + 21, WOOL)
    mc.setBlocks(x - 6, y + 39, z - 2, x + 33, y + 39, z + 21, WOOL)
    mc.setBlocks(x - 6, y + 22, z - 2, x + 33, y + 39, z - 2, WOOL)
    mc.setBlocks(x - 6, y + 22, z + 21, x + 33, y + 39, z + 21, WOOL)
    mc.setBlocks(x - 6, y + 22, z - 2, x - 6, y + 39, z + 21, WOOL)
    mc.setBlocks(x + 33, y + 22, z - 2, x + 33, y + 39, z + 21, WOOL)


def head(x, y, z, WOOL):
    mc.setBlocks(x + 1, y + 32, z + 3, x + 1, y + 45, z + 16, WOOL)
    mc.setBlocks(x + 1, y + 32, z + 3, x - 12, y + 45, z + 3, WOOL)
    mc.setBlocks(x + 1, y + 32, z + 16, x - 12, y + 45, z + 16, WOOL)
    mc.setBlocks(x + 1, y + 32, z + 3, x - 12, y + 32, z + 16, WOOL)
    mc.setBlocks(x + 1, y + 45, z + 3, x - 12, y + 45, z + 16, WOOL)


def face(x, y, z):
    mc.setBlocks(x - 14, y + 33, z + 4, x - 13, y + 44, z + 15, param.WHITE_WOOL)
    mc.setBlocks(x - 14, y + 37, z + 4, x - 13, y + 42, z + 15, param.WHITE_TERRACOTTA)
    mc.setBlocks(x - 14, y + 33, z + 6, x - 13, y + 36, z + 13, param.WHITE_TERRACOTTA)
    mc.setBlocks(x - 14, y + 33, z + 8, x - 14, y + 36, z + 11, param.PINK_CONCRETE)
    mc.setBlocks(x - 14, y + 39, z + 4, x - 14, y + 40, z + 5, param.BLACK_CONCRETE)
    mc.setBlocks(x - 14, y + 39, z + 14, x - 14, y + 40, z + 15, param.BLACK_CONCRETE)
    mc.setBlocks(x - 14, y + 39, z + 6, x - 13, y + 40, z + 7, param.WHITE_CONCRETE)
    mc.setBlocks(x - 14, y + 39, z + 12, x - 13, y + 40, z + 13, param.WHITE_CONCRETE)


def spawn(x=0, y=63, z=0):
    color = rd.randint(1, 16)
    if color == 1:
        WOOL = param.WHITE_WOOL
    elif color == 2:
        WOOL = param.ORANGE_WOOL
    elif color == 3:
        WOOL = param.MAGENTA_WOOL
    elif color == 4:
        WOOL = param.LIGHT_BLUE_WOOL
    elif color == 5:
        WOOL = param.YELLOW_WOOL
    elif color == 6:
        WOOL = param.LIME_WOOL
    elif color == 7:
        WOOL = param.PINK_CONCRETE
    elif color == 8:
        WOOL = param.GRAY_WOOL
    elif color == 9:
        WOOL = param.LIGHT_GRAY_WOOL
    elif color == 10:
        WOOL = param.CYAN_WOOL
    elif color == 11:
        WOOL = param.PURPLE_WOOL
    elif color == 12:
        WOOL = param.BLUE_WOOL
    elif color == 13:
        WOOL = param.BROWN_WOOL
    elif color == 14:
        WOOL = param.GREEN_WOOL
    elif color == 15:
        WOOL = param.RED_WOOL
    else:
        WOOL = param.BLACK_WOOL
    leg(x, y, z, WOOL)             # 右前足
    leg(x, y, z + 12, WOOL)        # 左前足
    leg(x + 24, y, z, WOOL)        # 右後足
    leg(x + 24, y, z + 12, WOOL)   # 左後足
    body(x, y, z, WOOL)
    head(x, y, z, WOOL)
    face(x, y, z)
    mc.postToChat('spawn sheep')


# ------------ despawn ------------ #
def c_leg(x, y, z):
    mc.setBlocks(x, y, z, x + 7, y + 1, z + 7, param.AIR)
    mc.setBlocks(x + 2, y, z + 2, x + 7, y + 1, z + 5, param.AIR)
    mc.setBlocks(x, y + 2, z, x + 7, y + 11, z + 7, param.AIR)
    mc.setBlocks(x - 1, y + 12, z - 1, x + 8, y + 21, z + 8, param.AIR)


def c_body(x, y, z):
    mc.setBlocks(x - 6, y + 22, z - 2, x + 33, y + 22, z + 21, param.AIR)
    mc.setBlocks(x - 6, y + 39, z - 2, x + 33, y + 39, z + 21, param.AIR)
    mc.setBlocks(x - 6, y + 22, z - 2, x + 33, y + 39, z - 2, param.AIR)
    mc.setBlocks(x - 6, y + 22, z + 21, x + 33, y + 39, z + 21, param.AIR)
    mc.setBlocks(x - 6, y + 22, z - 2, x - 6, y + 39, z + 21, param.AIR)
    mc.setBlocks(x + 33, y + 22, z - 2, x + 33, y + 39, z + 21, param.AIR)


def c_head(x, y, z):
    mc.setBlocks(x + 1, y + 32, z + 3, x + 1, y + 45, z + 16, param.AIR)
    mc.setBlocks(x + 1, y + 32, z + 3, x - 12, y + 45, z + 3, param.AIR)
    mc.setBlocks(x + 1, y + 32, z + 16, x - 12, y + 45, z + 16, param.AIR)
    mc.setBlocks(x + 1, y + 32, z + 3, x - 12, y + 32, z + 16, param.AIR)
    mc.setBlocks(x + 1, y + 45, z + 3, x - 12, y + 45, z + 16, param.AIR)


def c_face(x, y, z):
    mc.setBlocks(x - 14, y + 33, z + 4, x - 13, y + 44, z + 15, param.AIR)
    mc.setBlocks(x - 14, y + 37, z + 4, x - 13, y + 42, z + 15, param.AIR)
    mc.setBlocks(x - 14, y + 33, z + 6, x - 13, y + 36, z + 13, param.AIR)
    mc.setBlocks(x - 14, y + 33, z + 8, x - 14, y + 36, z + 11, param.AIR)
    mc.setBlocks(x - 14, y + 39, z + 4, x - 14, y + 40, z + 5, param.AIR)
    mc.setBlocks(x - 14, y + 39, z + 14, x - 14, y + 40, z + 15, param.AIR)
    mc.setBlocks(x - 14, y + 39, z + 6, x - 13, y + 40, z + 7, param.AIR)
    mc.setBlocks(x - 14, y + 39, z + 12, x - 13, y + 40, z + 13, param.AIR)


def despawn(x=0, y=63, z=0):
    c_leg(x, y, z)             # 右前足
    c_leg(x, y, z + 12)        # 左前足
    c_leg(x + 24, y, z)        # 右後足
    c_leg(x + 24, y, z + 12)   # 左後足
    c_body(x, y, z)
    c_head(x, y, z)
    c_face(x, y, z)
    mc.postToChat('despawn sheep')
